Workbook

Sheet Parameters
A1: Probability | B1: 0.25
A2: Mean | B2: 35
A3: StdDev | B3: 7

Sheet Data
A1: Data | B1: Groups
A2: =ROUND(_xlfn.NORM.INV(RAND(),Parameters!$B$2,Parameters!$B$3),0) -> 35 | B2: =RANDBETWEEN(1,4) -> 2
A3: =ROUND(_xlfn.NORM.INV(RAND(),Parameters!$B$2,Parameters!$B$3),0) -> 37 | B3: =RANDBETWEEN(1,4) -> 1
A4: =ROUND(_xlfn.NORM.INV(RAND(),Parameters!$B$2,Parameters!$B$3),0) -> 31 | B4: =RANDBETWEEN(1,4) -> 2
A5: =ROUND(_xlfn.NORM.INV(RAND(),Parameters!$B$2,Parameters!$B$3),0) -> 37 | B5: =RANDBETWEEN(1,4) -> 3
A6: =ROUND(_xlfn.NORM.INV(RAND(),Parameters!$B$2,Parameters!$B$3),0) -> 43 | B6: =RANDBETWEEN(1,4) -> 4
A7: =ROUND(_xlfn.NORM.INV(RAND(),Parameters!$B$2,Parameters!$B$3),0) -> 33 | B7: =RANDBETWEEN(1,4) -> 2
A8: =ROUND(_xlfn.NORM.INV(RAND(),Parameters!$B$2,Parameters!$B$3),0) -> 34 | B8: =RANDBETWEEN(1,4) -> 3
A9: =ROUND(_xlfn.NORM.INV(RAND(),Parameters!$B$2,Parameters!$B$3),0) -> 23 | B9: =RANDBETWEEN(1,4) -> 2
A10: =ROUND(_xlfn.NORM.INV(RAND(),Parameters!$B$2,Parameters!$B$3),0) -> 35 | B10: =RANDBETWEEN(1,4) -> 3
A11: =ROUND(_xlfn.NORM.INV(RAND(),Parameters!$B$2,Parameters!$B$3),0) -> 32 | B11: =RANDBETWEEN(1,4) -> 3
A12: =ROUND(_xlfn.NORM.INV(RAND(),Parameters!$B$2,Parameters!$B$3),0) -> 38 | B12: =RANDBETWEEN(1,4) -> 2
A13: =ROUND(_xlfn.NORM.INV(RAND(),Parameters!$B$2,Parameters!$B$3),0) -> 29 | B13: =RANDBETWEEN(1,4) -> 1
... A251: =ROUND(_xlfn.NORM.INV(RAND(),Parameters!$B$2,Parameters!$B$3),0) -> 29 | B251: =RANDBETWEEN(1,4) -> 1

Sheet Sample
A1: Data | B1: Groups | C1: Sample data
A2: 31 | B2: 3 | C2: =IF(B2=2,A2,"Falso") -> Falso
A3: 27 | B3: 1 | C3: =IF(B3=2,A3,"Falso") -> Falso
A4: 33 | B4: 2 | C4: =IF(B4=2,A4,"Falso") -> 33
A5: 32 | B5: 1 | C5: =IF(B5=2,A5,"Falso") -> Falso
A6: 26 | B6: 3 | C6: =IF(B6=2,A6,"Falso") -> Falso
A7: 41 | B7: 1 | C7: =IF(B7=2,A7,"Falso") -> Falso
A8: 30 | B8: 3 | C8: =IF(B8=2,A8,"Falso") -> Falso
A9: 20 | B9: 3 | C9: =IF(B9=2,A9,"Falso") -> Falso
A10: 27 | B10: 1 | C10: =IF(B10=2,A10,"Falso") -> Falso
A11: 36 | B11: 4 | C11: =IF(B11=2,A11,"Falso") -> Falso
A12: 31 | B12: 4 | C12: =IF(B12=2,A12,"Falso") -> Falso
A13: 23 | B13: 1 | C13: =IF(B13=2,A13,"Falso") -> Falso
... A251: 41 | B251: 1 | C251: =IF(B251=2,A251,"Falso") -> Falso

Sheet Statistical insight
A1: STDDEV | B1: =SQRT(_xlfn.VAR.S(Sample!A2:A251)) -> 6.8066823 | D1: Conoscendo la varianza della popolazione, per calcolare l'intervallo di confidenza è possibile utilizzare la distribuzione Normale. Quindi ponendo come di solito la probabilità a=0,05, avrò che Z è calcolata con la formula INV.NORM.S(0,975), poichè 0,975 è il complementare a 1 della probabilità a=0,05 + a/2 che è uguale a 0,025. Applicando la formula con tale probabilità per ogni coda, si ottengono il limite inferiore e il limite superiore di un certo intervallo di confidenza che contiene la media. Partendo dai dati assegnati nel primo tab, in questo studio abbiamo una media campionaria che poco si discosta da quella assegnata alla popolazione di partenza, pertanto si dimostra la validità dello studio inferenziale.
A2: EXPECTED VALUE | B2: =AVERAGE(Sample!C4:C247) -> 36.75
A3: COUNT | B3: =COUNT(Sample!C4:C247) -> 56
A4: CONFIDENCE RATE | B4: 0.05
A5: Estimation of p parameter | B5: =_xlfn.NORM.S.INV(0.975) -> 1.959964
A6: Confidence interval | B6: =B2-B5*(B1/SQRT(B3)) -> 34.967254 | C6: =B2+B5*(B1/SQRT(B3)) -> 38.532746
D7: Sappiamo che la varianza identifica la dispersione dei valori della variabile attorno al valor medio. Quanto più piccola è la varianza, tanto più i valori della variabile sono concentrati attorno al valor medio. Nel primo tab la deviazione standard scelta è molto bassa, per cui tutti i valori della distribuzione non si discostano dalla media della popolazione, questo comporta che tale caratteristica sarà presente anche in un campione estratto casualmente dalla stessa popolazione. Per cui la media del campione non sarà molto diversa da quella della popolazione. Si conclude quindi che la precisione di un campione è maggiore quando la popolazione da cui è stato estratto è tendenzialmente omogenea. Nel nostro caso il campione ha n=56, rispetto a n=250 della popolazione, quindi il campione è circa il 22% della popolazione, potrebbe sembrare non rappresentativo della popolazione rispetto a campioni più grandi, ma vista la deviazione standard scelta (bassa), la popolazione ha una distribuzione con pochi scarti dalla media. Questo farà sì che anche i campioni estratti avranno scarti bassi e valore medio non molto distante da quello della popolazione. A dimostrazione di quanto detto, a sinistra abbiamo il valore medio degli altri gruppi della popolazione non considerati in questo tab, mentre a destra un campione estratto casualmente di n=10. In tutti i campioni, sia in quelli con dimensione simile al campione di studio nel tab che in quello molto più piccolo, la media ottenuta ha un valore comunque non molto distante da quello della popolazione. Ciò è possibile con una devizione standard abbastanza contenuta.
A12: ALTRI GRUPPI DELLA POPOLAZIONE | B12: MEDIA | J12: Campione n=10 | K12: MEDIA
A13: 1 | B13: 34 | J13: 33 | K13: =AVERAGE(J13:J22) -> 32.1
A14: 3 | B14: 33 | J14: 29
A15: 4 | B15: 35 | J15: 30
J16: 39
J17: 35
J18: 37
J19: 32
J20: 28
J21: 35
J22: 23

Sheet (Un)correlated variables
A1: Sample data | B1: Number of cats | C1: Age of partner
A2: 33 | B2: 5 | C2: =$H$3*A2+(SQRT(1-($H$3)^2)*B2) -> 29.921818 | G2: Correlation age and cats | H2: =PEARSON(A2:A57,B2:B57) -> -0.068288475 | I2: Assenza di Correlazione
A3: 30 | B3: 6 | C3: =$H$3*A3+(SQRT(1-($H$3)^2)*B3) -> 28.034181 | G3: Desired correlation(r) | H3: 0.82
A4: 35 | B4: 5 | C4: =$H$3*A4+(SQRT(1-($H$3)^2)*B4) -> 31.561818 | G4: Actual correlation(r') | H4: =PEARSON(A2:A57,C2:C57) -> 0.98081827 | I4: Correlazione positiva
A5: 23 | B5: 7 | C5: =$H$3*A5+(SQRT(1-($H$3)^2)*B5) -> 22.866545
A6: 49 | B6: 5 | C6: =$H$3*A6+(SQRT(1-($H$3)^2)*B6) -> 43.041818
A7: 36 | B7: 4 | C7: =$H$3*A7+(SQRT(1-($H$3)^2)*B7) -> 31.809454
A8: 50 | B8: 2 | C8: =$H$3*A8+(SQRT(1-($H$3)^2)*B8) -> 42.144727
A9: 30 | B9: 5 | C9: =$H$3*A9+(SQRT(1-($H$3)^2)*B9) -> 27.461818
A10: 37 | B10: 2 | C10: =$H$3*A10+(SQRT(1-($H$3)^2)*B10) -> 31.484727
A11: 39 | B11: 4 | C11: =$H$3*A11+(SQRT(1-($H$3)^2)*B11) -> 34.269454
A12: 39 | B12: 5 | C12: =$H$3*A12+(SQRT(1-($H$3)^2)*B12) -> 34.841818
A13: 53 | B13: 4 | C13: =$H$3*A13+(SQRT(1-($H$3)^2)*B13) -> 45.749454
A14: 26 | B14: 1 | C14: =$H$3*A14+(SQRT(1-($H$3)^2)*B14) -> 21.892364
A15: 34 | B15: 4 | C15: =$H$3*A15+(SQRT(1-($H$3)^2)*B15) -> 30.169454
A16: 42 | B16: 4 | C16: =$H$3*A16+(SQRT(1-($H$3)^2)*B16) -> 36.729454
... A57: 30 | B57: 6 | C57: =$H$3*A57+(SQRT(1-($H$3)^2)*B57) -> 28.034181

Sheet Linear regression
A1: Y (age) | B1: X (rank) | D1: Ipotesi Età | E1: Età stimata
A2: 18.937091 | B2: 1 | D2: 113 | E2: {=ROUND(_xlfn.FORECAST.LINEAR(D2:D49,A2:A113,B2:B113),0)} -> 46
A3: 21 | B3: 2 | D3: 114 | E3: 46
A4: 21.892364 | B4: 3 | D4: 115 | E4: 46
A5: 22.712364 | B5: 4 | D5: 116 | E5: 47
A6: 22.866545 | B6: 5 | D6: 117 | E6: 47
A7: 23 | B7: 6 | D7: 118 | E7: 47
A8: 23.037091 | B8: 7 | D8: 119 | E8: 47
A9: 24.104727 | B9: 8 | D9: 120 | E9: 47
A10: 24.352364 | B10: 9 | D10: 121 | E10: 48
A11: 25.574181 | B11: 10 | D11: 122 | E11: 48
A12: 26 | B12: 11 | D12: 123 | E12: 48
A13: 26 | B13: 12 | D13: 124 | E13: 48
A14: 27 | B14: 13 | D14: 125 | E14: 48
... A17: 28 | B17: 16 | D17: 128 | E17: 49
A18: 28.034181 | B18: 17 | D18: 129 | E18: 49 | G18: Con il coefficiente di regressione=0,9484, quindi molto vicino a 1, si evidenzia il buon adattamento del modello di regressione. Come si nota dalla retta di regressione i dati in esame avranno una tendenza positiva per X superiori a quelli del campione. Infatti nel calcolo dell'estrapolazione per il 160° individuo abbiamo un'età in linea con i dati osservati: all'aumentare del Rank (ordinamento dei soggetti), aumentano le età anagrafiche degli individui soggetti all'indagine statistica. Si tratta in realtà di un'indagine poco significante e/o scontata dal punto di vista informativo , ma bene spiega la significatività di media e varianza scelte nel primo tab, dati dai quali è stata generata la tabella statistica oggetto di studio del Progetto: i due valori sono molto contenuti per cui otteniamo che il 160° individuo della statistica avrà 55 anni. Con media e varianza molto più elevate avremmo avuto certamente un'età altrettanto elevata, se non impossibile dal punto di vista della longevità umana, quindi poco realistica.
A19: 28.034181 | B19: 18 | D19: 130 | E19: 49
A20: 28.204727 | B20: 19 | D20: 131 | E20: 50
A21: 28.777091 | B21: 20 | D21: 132 | E21: 50
A22: 29 | B22: 21 | D22: 133 | E22: 50
A23: 29.921818 | B23: 22 | D23: 134 | E23: 50
A24: 29.921818 | B24: 23 | D24: 135 | E24: 50
A25: 30 | B25: 24 | D25: 136 | E25: 51
A26: 30 | B26: 25 | D26: 137 | E26: 51
A27: 30 | B27: 26 | D27: 138 | E27: 51
A28: 30.169454 | B28: 27 | D28: 139 | E28: 51
A29: 30.246545 | B29: 28 | D29: 140 | E29: 51
A30: 30.741818 | B30: 29 | D30: 141 | E30: 52
... A49: 33 | B49: 48 | D49: 160 | E49: 55
A50: 33 | B50: 49
A51: 33.526545 | B51: 50
A52: 33.697091 | B52: 51
A53: 33.944727 | B53: 52
A54: 34 | B54: 53
A55: 34 | B55: 54
A56: 34 | B56: 55
A57: 34 | B57: 56
A58: 34.269454 | B58: 57
A59: 34.346545 | B59: 58
A60: 34.517091 | B60: 59
...
