Workbook

Sheet My trades
A1: Trade | B1: Stock exchange | C1: Region | D1: Date added | E1: Quantity | F1: Buy Price | G1: Date sold | H1: Sell Price
A2: agfgcfxt | B2: Bombay Stock Exchange | C2: India | D2: 44841 | E2: 7 | F2: 0.28318547 | G2: 45092 | H2: 0.55712981
A3: aieoltom | B3: Tehran Stock Exchange | C3: Iran | D3: 44200 | E3: 2 | F3: 0.64142747 | G3: 45039 | H3: 0.88983598
A4: almuieaq | B4: National Stock Exchange | C4: India | D4: 44519 | E4: 6 | F4: 0.98092818 | G4: 44968 | H4: 0.72256313
A5: apxkynfx | B5: SIX Swiss Exchange | C5: Switzerland | D5: 44664 | E5: 1 | F5: 0.4602753 | G5: 44971 | H5: 0.8279317
A6: bbjeprsq | B6: Bombay Stock Exchange | C6: India | D6: 44351 | E6: 9 | F6: 0.55179845 | G6: 44977 | H6: 0.19789786
A7: bcizkhng | B7: Euronext | C7: Europe | D7: 44529 | E7: 1 | F7: 0.30386849 | G7: 44969 | H7: 0.97814413
A8: bdkloegq | B8: Korea Exchange | C8: South Korea | D8: 44500 | E8: 3 | F8: 0.10094556 | G8: 44930 | H8: 0.40740538
A9: beszhcyh | B9: Johannesburg Stock Exchange | C9: South Africa | D9: 44584 | E9: 4 | F9: 0.1365207 | G9: 44991 | H9: 0.38969057
A10: bjfxoyxb | B10: Toronto Stock Exchange | C10: Canada | D10: 44472 | E10: 10 | F10: 0.41670439 | G10: 45045 | H10: 0.54934508
A11: bpjmrhjo | B11: Euronext | C11: Europe | D11: 44587 | E11: 6 | F11: 0.24316987 | G11: 44987 | H11: 0.42023282
A12: brxwzrct | B12: Deutsche Börse AG | C12: Germany | D12: 44407 | E12: 5 | F12: 0.80079383 | G12: 44996 | H12: 0.8966623
A13: bumcnvke | B13: Bombay Stock Exchange | C13: India | D13: 44543 | E13: 10 | F13: 0.63898127 | G13: 45031 | H13: 0.77496722
... A201: zvxjotpr | B201: B3 Brasil Bolsa Balcão | C201: Brazil | D201: 44502 | E201: 8 | F201: 0.91352809 | G201: 44978 | H201: 0.13798579
D203: ​

Sheet Stock exchanges
A1: Region | B1: Stock exchange | C1: Num of trades | D1: Mandatory to pay taxes | G1: Region | H1: Conteggio di Stock exchange | I1: Somma di Quantity
A2: Australia | B2: 16 | C2: 80 | D2: =IF(C2>=67,"YES","NO") -> YES | G2: Australia | H2: 16 | I2: 80
A3: Brazil | B3: 16 | C3: 83 | D3: =IF(C3>=67,"YES","NO") -> YES | G3: Brazil | H3: 16 | I3: 83
A4: Canada | B4: 8 | C4: 46 | D4: =IF(C4>=67,"YES","NO") -> NO | G4: Canada | H4: 8 | I4: 46
A5: China | B5: 16 | C5: 74 | D5: =IF(C5>=67,"YES","NO") -> YES | G5: China | H5: 16 | I5: 74
A6: Europe | B6: 16 | C6: 70 | D6: =IF(C6>=67,"YES","NO") -> YES | G6: Europe | H6: 16 | I6: 70
A7: Germany | B7: 16 | C7: 81 | D7: =IF(C7>=67,"YES","NO") -> YES | G7: Germany | H7: 16 | I7: 81
A8: Hong Kong | B8: 8 | C8: 54 | D8: =IF(C8>=67,"YES","NO") -> NO | G8: Hong Kong | H8: 8 | I8: 54
A9: India | B9: 24 | C9: 111 | D9: =IF(C9>=67,"YES","NO") -> YES | G9: India | H9: 24 | I9: 111
A10: Iran | B10: 8 | C10: 40 | D10: =IF(C10>=67,"YES","NO") -> NO | G10: Iran | H10: 8 | I10: 40
A11: Japan | B11: 8 | C11: 43 | D11: =IF(C11>=67,"YES","NO") -> NO | G11: Japan | H11: 8 | I11: 43
A12: Saudi Arabia | B12: 8 | C12: 35 | D12: =IF(C12>=67,"YES","NO") -> NO | G12: Saudi Arabia | H12: 8 | I12: 35
A13: South Africa | B13: 8 | C13: 34 | D13: =IF(C13>=67,"YES","NO") -> NO | G13: South Africa | H13: 8 | I13: 34
... A18: United States | B18: 16 | C18: 88 | D18: =IF(C18>=67,"YES","NO") -> YES | G18: United States | H18: 16 | I18: 88
A19: Totale complessivo | B19: 200 | C19: 1019 | G19: Totale complessivo | H19: 200 | I19: 1019

Sheet Profit insights
A1: TradeID | B1: Duration | C1: Profit
A2: ='My trades'!A2 -> agfgcfxt | B2: ='My trades'!G2-'My trades'!D2 -> 251 | C2: =('My trades'!H2-'My trades'!F2)*'My trades'!E2 -> 1.9176104 | N2: Min | O2: =MIN(B2:B201) -> 30
A3: ='My trades'!A3 -> aieoltom | B3: ='My trades'!G3-'My trades'!D3 -> 839 | C3: =('My trades'!H3-'My trades'!F3)*'My trades'!E3 -> 0.49681702 | N3: Max | O3: =MAX(B2:B201) -> 862
A4: ='My trades'!A4 -> almuieaq | B4: ='My trades'!G4-'My trades'!D4 -> 449 | C4: =('My trades'!H4-'My trades'!F4)*'My trades'!E4 -> -1.5501903 | N4: N. intervalli | O4: 20
A5: ='My trades'!A5 -> apxkynfx | B5: ='My trades'!G5-'My trades'!D5 -> 307 | C5: =('My trades'!H5-'My trades'!F5)*'My trades'!E5 -> 0.3676564 | N5: Ampiezza | O5: =(O3-O2)/O4 -> 41.6
A6: ='My trades'!A6 -> bbjeprsq | B6: ='My trades'!G6-'My trades'!D6 -> 626 | C6: =('My trades'!H6-'My trades'!F6)*'My trades'!E6 -> -3.1851053
A7: ='My trades'!A7 -> bcizkhng | B7: ='My trades'!G7-'My trades'!D7 -> 440 | C7: =('My trades'!H7-'My trades'!F7)*'My trades'!E7 -> 0.67427564 | P7: Classi di intervallo | Q7: Freq assolute
A8: ='My trades'!A8 -> bdkloegq | B8: ='My trades'!G8-'My trades'!D8 -> 430 | C8: =('My trades'!H8-'My trades'!F8)*'My trades'!E8 -> 0.91937946 | N8: Lim inf | O8: =MIN(B8:B207) -> 30 | P8: =O8 &"-"& O9 -> 30-71,6 | Q8: {=FREQUENCY($B$2:$B$201,O9:O27)} -> 7
A9: ='My trades'!A9 -> beszhcyh | B9: ='My trades'!G9-'My trades'!D9 -> 407 | C9: =('My trades'!H9-'My trades'!F9)*'My trades'!E9 -> 1.0126795 | N9: Limiti di intervalli | O9: =O8+$O$5 -> 71.6 | P9: =O9 &"-"& O10 -> 71,6-113,2 | Q9: 6
A10: ='My trades'!A10 -> bjfxoyxb | B10: ='My trades'!G10-'My trades'!D10 -> 573 | C10: =('My trades'!H10-'My trades'!F10)*'My trades'!E10 -> 1.3264069 | O10: =O9+$O$5 -> 113.2 | P10: =O10 &"-"& O11 -> 113,2-154,8 | Q10: 9
A11: ='My trades'!A11 -> bpjmrhjo | B11: ='My trades'!G11-'My trades'!D11 -> 400 | C11: =('My trades'!H11-'My trades'!F11)*'My trades'!E11 -> 1.0623777 | O11: =O10+$O$5 -> 154.8 | P11: =O11 &"-"& O12 -> 154,8-196,4 | Q11: 9
A12: ='My trades'!A12 -> brxwzrct | B12: ='My trades'!G12-'My trades'!D12 -> 589 | C12: =('My trades'!H12-'My trades'!F12)*'My trades'!E12 -> 0.47934231 | O12: =O11+$O$5 -> 196.4 | P12: =O12 &"-"& O13 -> 196,4-238 | Q12: 13
A13: ='My trades'!A13 -> bumcnvke | B13: ='My trades'!G13-'My trades'!D13 -> 488 | C13: =('My trades'!H13-'My trades'!F13)*'My trades'!E13 -> 1.3598595 | O13: =O12+$O$5 -> 238 | P13: =O13 &"-"& O14 -> 238-279,6 | Q13: 11
A14: ='My trades'!A14 -> cesjzpbs | B14: ='My trades'!G14-'My trades'!D14 -> 109 | C14: =('My trades'!H14-'My trades'!F14)*'My trades'!E14 -> 2.9151707 | O14: =O13+$O$5 -> 279.6 | P14: =O14 &"-"& O15 -> 279,6-321,2 | Q14: 11
A15: ='My trades'!A15 -> cetffxgx | B15: ='My trades'!G15-'My trades'!D15 -> 668 | C15: =('My trades'!H15-'My trades'!F15)*'My trades'!E15 -> 0.52361641 | O15: =O14+$O$5 -> 321.2 | P15: =O15 &"-"& O16 -> 321,2-362,8 | Q15: 10
A16: ='My trades'!A16 -> chhqshvn | B16: ='My trades'!G16-'My trades'!D16 -> 267 | C16: =('My trades'!H16-'My trades'!F16)*'My trades'!E16 -> -0.37738991 | O16: =O15+$O$5 -> 362.8 | P16: =O16 &"-"& O17 -> 362,8-404,4 | Q16: 10
A17: ='My trades'!A17 -> ciykrilb | B17: ='My trades'!G17-'My trades'!D17 -> 78 | C17: =('My trades'!H17-'My trades'!F17)*'My trades'!E17 -> -4.0381768 | O17: =O16+$O$5 -> 404.4 | P17: =O17 &"-"& O18 -> 404,4-446 | Q17: 15
A18: ='My trades'!A18 -> cnitsbpk | B18: ='My trades'!G18-'My trades'!D18 -> 762 | C18: =('My trades'!H18-'My trades'!F18)*'My trades'!E18 -> -0.17044593 | O18: =O17+$O$5 -> 446 | P18: =O18 &"-"& O19 -> 446-487,6 | Q18: 10
A19: ='My trades'!A19 -> cntrbotn | B19: ='My trades'!G19-'My trades'!D19 -> 623 | C19: =('My trades'!H19-'My trades'!F19)*'My trades'!E19 -> 0.44281899 | O19: =O18+$O$5 -> 487.6 | P19: =O19 &"-"& O20 -> 487,6-529,2 | Q19: 9
A20: ='My trades'!A20 -> cwuqczya | B20: ='My trades'!G20-'My trades'!D20 -> 862 | C20: =('My trades'!H20-'My trades'!F20)*'My trades'!E20 -> 0.29609314 | O20: =O19+$O$5 -> 529.2 | P20: =O20 &"-"& O21 -> 529,2-570,8 | Q20: 11
A21: ='My trades'!A21 -> cymioqte | B21: ='My trades'!G21-'My trades'!D21 -> 634 | C21: =('My trades'!H21-'My trades'!F21)*'My trades'!E21 -> 0.30170445 | O21: =O20+$O$5 -> 570.8 | P21: =O21 &"-"& O22 -> 570,8-612,4 | Q21: 12
A22: ='My trades'!A22 -> dcnexoao | B22: ='My trades'!G22-'My trades'!D22 -> 546 | C22: =('My trades'!H22-'My trades'!F22)*'My trades'!E22 -> -0.61275828 | E22: Nel diagramma è rappresentata la durata di mantenimento dei titoli espressa in giorni. Tale durata è calcolata considerando i giorni intercorsi tra la data di acquisto e la data di vendita del titolo. La distribuzione di tale Duration non è da considerarsi Normale, perchè non è campanulare, non è simmetrica rispetto alla media, inoltre Media, Moda e Mediana non coincidono. | O22: =O21+$O$5 -> 612.4 | P22: =O22 &"-"& O23 -> 612,4-654 | Q22: 11
A23: ='My trades'!A23 -> dcplrgaa | B23: ='My trades'!G23-'My trades'!D23 -> 708 | C23: =('My trades'!H23-'My trades'!F23)*'My trades'!E23 -> -2.5885468 | O23: =O22+$O$5 -> 654 | P23: =O23 &"-"& O24 -> 654-695,6 | Q23: 8
A24: ='My trades'!A24 -> dieionnl | B24: ='My trades'!G24-'My trades'!D24 -> 547 | C24: =('My trades'!H24-'My trades'!F24)*'My trades'!E24 -> 0.76109128 | O24: =O23+$O$5 -> 695.6 | P24: =O24 &"-"& O25 -> 695,6-737,2 | Q24: 12
A25: ='My trades'!A25 -> dlgsjszn | B25: ='My trades'!G25-'My trades'!D25 -> 237 | C25: =('My trades'!H25-'My trades'!F25)*'My trades'!E25 -> 0.4472007 | O25: =O24+$O$5 -> 737.2 | P25: =O25 &"-"& O26 -> 737,2-778,8 | Q25: 13
A26: ='My trades'!A26 -> dpaxyvrx | B26: ='My trades'!G26-'My trades'!D26 -> 51 | C26: =('My trades'!H26-'My trades'!F26)*'My trades'!E26 -> -0.32528107 | O26: =O25+$O$5 -> 778.8 | P26: =O26 &"-"& O27 -> 778,8-820,4 | Q26: 9
A27: ='My trades'!A27 -> dspetbsq | B27: ='My trades'!G27-'My trades'!D27 -> 207 | C27: =('My trades'!H27-'My trades'!F27)*'My trades'!E27 -> -5.4295327 | O27: =O26+$O$5 -> 820.4 | P27: =O27 &"-"& O28 -> 820,4-862 | Q27: 4
A28: ='My trades'!A28 -> ebkkmqbi | B28: ='My trades'!G28-'My trades'!D28 -> 465 | C28: =('My trades'!H28-'My trades'!F28)*'My trades'!E28 -> -3.8535105 | N28: Lim sup | O28: =O27+$O$5 -> 862
A29: ='My trades'!A29 -> egvfikiy | B29: ='My trades'!G29-'My trades'!D29 -> 557 | C29: =('My trades'!H29-'My trades'!F29)*'My trades'!E29 -> -0.076959515
A30: ='My trades'!A30 -> eknpqcge | B30: ='My trades'!G30-'My trades'!D30 -> 513 | C30: =('My trades'!H30-'My trades'!F30)*'My trades'!E30 -> 2.4324013
A31: ='My trades'!A31 -> ekteqlhb | B31: ='My trades'!G31-'My trades'!D31 -> 686 | C31: =('My trades'!H31-'My trades'!F31)*'My trades'!E31 -> 0.15328854
A32: ='My trades'!A32 -> emjmheht | B32: ='My trades'!G32-'My trades'!D32 -> 387 | C32: =('My trades'!H32-'My trades'!F32)*'My trades'!E32 -> 5.7730509
A33: ='My trades'!A33 -> eodhevfz | B33: ='My trades'!G33-'My trades'!D33 -> 795 | C33: =('My trades'!H33-'My trades'!F33)*'My trades'!E33 -> 5.8835677
A34: ='My trades'!A34 -> ewzlrcco | B34: ='My trades'!G34-'My trades'!D34 -> 499 | C34: =('My trades'!H34-'My trades'!F34)*'My trades'!E34 -> 2.9976291
A35: ='My trades'!A35 -> fenldjbq | B35: ='My trades'!G35-'My trades'!D35 -> 607 | C35: =('My trades'!H35-'My trades'!F35)*'My trades'!E35 -> -2.7592838
A36: ='My trades'!A36 -> fipcayvv | B36: ='My trades'!G36-'My trades'!D36 -> 434 | C36: =('My trades'!H36-'My trades'!F36)*'My trades'!E36 -> -0.62411903
A37: ='My trades'!A37 -> fjcdzhde | B37: ='My trades'!G37-'My trades'!D37 -> 851 | C37: =('My trades'!H37-'My trades'!F37)*'My trades'!E37 -> -1.4878863
A38: ='My trades'!A38 -> fjhbimle | B38: ='My trades'!G38-'My trades'!D38 -> 130 | C38: =('My trades'!H38-'My trades'!F38)*'My trades'!E38 -> -0.41919268
A39: ='My trades'!A39 -> fkgjitio | B39: ='My trades'!G39-'My trades'!D39 -> 448 | C39: =('My trades'!H39-'My trades'!F39)*'My trades'!E39 -> -2.2252396
A40: ='My trades'!A40 -> frlnnmpc | B40: ='My trades'!G40-'My trades'!D40 -> 482 | C40: =('My trades'!H40-'My trades'!F40)*'My trades'!E40 -> -4.8240735
...

Sheet Number of trades exchanged
C1: Number of trades
C2: 1 | D2: 2 | E2: 3 | F2: 4 | G2: 5 | H2: 6 | I2: 7 | J2: 8 | K2: 9 | L2: 10 | M2: Distr. Marginale
A3: Region | B3: {=_xlfn.UNIQUE('My trades'!C2:C201)} -> India | C3: =COUNTIFS('My trades'!$C$2:$C$201,'Number of trades exchanged'!$B$3,'My trades'!$E$2:$E$201,'Number of trades exchanged'!C2) -> 4 | D3: =COUNTIFS('My trades'!$C$2:$C$201,'Number of trades exchanged'!$B$3,'My trades'!$E$2:$E$201,'Number of trades exchanged'!D2) -> 4 | E3: =COUNTIFS('My trades'!$C$2:$C$201,'Number of trades exchanged'!$B$3,'My trades'!$E$2:$E$201,'Number of trades exchanged'!E2) -> 4 | F3: =COUNTIFS('My trades'!$C$2:$C$201,'Number of trades exchanged'!$B$3,'My trades'!$E$2:$E$201,'Number of trades exchanged'!F2) -> 1 | G3: =COUNTIFS('My trades'!$C$2:$C$201,'Number of trades exchanged'!$B$3,'My trades'!$E$2:$E$201,'Number of trades exchanged'!G2) -> 1 | H3: =COUNTIFS('My trades'!$C$2:$C$201,'Number of trades exchanged'!$B$3,'My trades'!$E$2:$E$201,'Number of trades exchanged'!H2) -> 3 | I3: =COUNTIFS('My trades'!$C$2:$C$201,'Number of trades exchanged'!$B$3,'My trades'!$E$2:$E$201,'Number of trades exchanged'!I2) -> 2 | J3: =COUNTIFS('My trades'!$C$2:$C$201,'Number of trades exchanged'!$B$3,'My trades'!$E$2:$E$201,'Number of trades exchanged'!J2) -> 1 | ... L3: =COUNTIFS('My trades'!$C$2:$C$201,'Number of trades exchanged'!$B$3,'My trades'!$E$2:$E$201,'Number of trades exchanged'!L2) -> 2 | M3: =SUM(C3:L3) -> 24
B4: Iran | C4: =COUNTIFS('My trades'!$C$2:$C$201,$B$4,'My trades'!$E$2:$E$201,'Number of trades exchanged'!C2) -> 0 | D4: =COUNTIFS('My trades'!$C$2:$C$201,$B$4,'My trades'!$E$2:$E$201,'Number of trades exchanged'!D2) -> 2 | E4: =COUNTIFS('My trades'!$C$2:$C$201,$B$4,'My trades'!$E$2:$E$201,'Number of trades exchanged'!E2) -> 1 | F4: =COUNTIFS('My trades'!$C$2:$C$201,$B$4,'My trades'!$E$2:$E$201,'Number of trades exchanged'!F2) -> 1 | G4: =COUNTIFS('My trades'!$C$2:$C$201,$B$4,'My trades'!$E$2:$E$201,'Number of trades exchanged'!G2) -> 1 | H4: =COUNTIFS('My trades'!$C$2:$C$201,$B$4,'My trades'!$E$2:$E$201,'Number of trades exchanged'!H2) -> 1 | I4: =COUNTIFS('My trades'!$C$2:$C$201,$B$4,'My trades'!$E$2:$E$201,'Number of trades exchanged'!I2) -> 0 | J4: =COUNTIFS('My trades'!$C$2:$C$201,$B$4,'My trades'!$E$2:$E$201,'Number of trades exchanged'!J2) -> 1 | ... L4: =COUNTIFS('My trades'!$C$2:$C$201,$B$4,'My trades'!$E$2:$E$201,'Number of trades exchanged'!L2) -> 1 | M4: =SUM(C4:L4) -> 8 | N4: P(UK,7)= | O4: =I15/M20 -> 0.01
B5: Switzerland | C5: =COUNTIFS('My trades'!$C$2:$C$201,$B$5,'My trades'!$E$2:$E$201,'Number of trades exchanged'!C2) -> 2 | D5: =COUNTIFS('My trades'!$C$2:$C$201,$B$5,'My trades'!$E$2:$E$201,'Number of trades exchanged'!D2) -> 0 | E5: =COUNTIFS('My trades'!$C$2:$C$201,$B$5,'My trades'!$E$2:$E$201,'Number of trades exchanged'!E2) -> 0 | F5: =COUNTIFS('My trades'!$C$2:$C$201,$B$5,'My trades'!$E$2:$E$201,'Number of trades exchanged'!F2) -> 0 | G5: =COUNTIFS('My trades'!$C$2:$C$201,$B$5,'My trades'!$E$2:$E$201,'Number of trades exchanged'!G2) -> 0 | H5: =COUNTIFS('My trades'!$C$2:$C$201,$B$5,'My trades'!$E$2:$E$201,'Number of trades exchanged'!H2) -> 2 | I5: =COUNTIFS('My trades'!$C$2:$C$201,$B$5,'My trades'!$E$2:$E$201,'Number of trades exchanged'!I2) -> 0 | J5: =COUNTIFS('My trades'!$C$2:$C$201,$B$5,'My trades'!$E$2:$E$201,'Number of trades exchanged'!J2) -> 2 | ... L5: =COUNTIFS('My trades'!$C$2:$C$201,$B$5,'My trades'!$E$2:$E$201,'Number of trades exchanged'!L2) -> 1 | M5: =SUM(C5:L5) -> 8 | N5: P(Asiatico <=8) | O5: =(SUM(C3:J3,C4:J4,C7:J7,C11:J11,C12:J12,C13:J13,C14:J14,C18:J18))/M20 -> 0.37
B6: Europe | C6: =COUNTIFS('My trades'!$C$2:$C$201,$B$6,'My trades'!$E$2:$E$201,'Number of trades exchanged'!C2) -> 3 | D6: =COUNTIFS('My trades'!$C$2:$C$201,$B$6,'My trades'!$E$2:$E$201,'Number of trades exchanged'!D2) -> 1 | E6: =COUNTIFS('My trades'!$C$2:$C$201,$B$6,'My trades'!$E$2:$E$201,'Number of trades exchanged'!E2) -> 2 | F6: =COUNTIFS('My trades'!$C$2:$C$201,$B$6,'My trades'!$E$2:$E$201,'Number of trades exchanged'!F2) -> 3 | G6: =COUNTIFS('My trades'!$C$2:$C$201,$B$6,'My trades'!$E$2:$E$201,'Number of trades exchanged'!G2) -> 2 | H6: =COUNTIFS('My trades'!$C$2:$C$201,$B$6,'My trades'!$E$2:$E$201,'Number of trades exchanged'!H2) -> 3 | I6: =COUNTIFS('My trades'!$C$2:$C$201,$B$6,'My trades'!$E$2:$E$201,'Number of trades exchanged'!I2) -> 0 | J6: =COUNTIFS('My trades'!$C$2:$C$201,$B$6,'My trades'!$E$2:$E$201,'Number of trades exchanged'!J2) -> 0 | ... L6: =COUNTIFS('My trades'!$C$2:$C$201,$B$6,'My trades'!$E$2:$E$201,'Number of trades exchanged'!L2) -> 1 | M6: =SUM(C6:L6) -> 16
B7: South Korea | C7: =COUNTIFS('My trades'!$C$2:$C$201,$B$7,'My trades'!$E$2:$E$201,'Number of trades exchanged'!C2) -> 2 | D7: =COUNTIFS('My trades'!$C$2:$C$201,$B$7,'My trades'!$E$2:$E$201,'Number of trades exchanged'!D2) -> 0 | E7: =COUNTIFS('My trades'!$C$2:$C$201,$B$7,'My trades'!$E$2:$E$201,'Number of trades exchanged'!E2) -> 2 | F7: =COUNTIFS('My trades'!$C$2:$C$201,$B$7,'My trades'!$E$2:$E$201,'Number of trades exchanged'!F2) -> 0 | G7: =COUNTIFS('My trades'!$C$2:$C$201,$B$7,'My trades'!$E$2:$E$201,'Number of trades exchanged'!G2) -> 0 | H7: =COUNTIFS('My trades'!$C$2:$C$201,$B$7,'My trades'!$E$2:$E$201,'Number of trades exchanged'!H2) -> 1 | I7: =COUNTIFS('My trades'!$C$2:$C$201,$B$7,'My trades'!$E$2:$E$201,'Number of trades exchanged'!I2) -> 2 | J7: =COUNTIFS('My trades'!$C$2:$C$201,$B$7,'My trades'!$E$2:$E$201,'Number of trades exchanged'!J2) -> 1 | ... L7: =COUNTIFS('My trades'!$C$2:$C$201,$B$7,'My trades'!$E$2:$E$201,'Number of trades exchanged'!L2) -> 0 | M7: =SUM(C7:L7) -> 8
B8: South Africa | C8: =COUNTIFS('My trades'!$C$2:$C$201,$B$8,'My trades'!$E$2:$E$201,'Number of trades exchanged'!C2) -> 2 | D8: =COUNTIFS('My trades'!$C$2:$C$201,$B$8,'My trades'!$E$2:$E$201,'Number of trades exchanged'!D2) -> 0 | E8: =COUNTIFS('My trades'!$C$2:$C$201,$B$8,'My trades'!$E$2:$E$201,'Number of trades exchanged'!E2) -> 1 | F8: =COUNTIFS('My trades'!$C$2:$C$201,$B$8,'My trades'!$E$2:$E$201,'Number of trades exchanged'!F2) -> 2 | G8: =COUNTIFS('My trades'!$C$2:$C$201,$B$8,'My trades'!$E$2:$E$201,'Number of trades exchanged'!G2) -> 1 | H8: =COUNTIFS('My trades'!$C$2:$C$201,$B$8,'My trades'!$E$2:$E$201,'Number of trades exchanged'!H2) -> 1 | I8: =COUNTIFS('My trades'!$C$2:$C$201,$B$8,'My trades'!$E$2:$E$201,'Number of trades exchanged'!I2) -> 0 | J8: =COUNTIFS('My trades'!$C$2:$C$201,$B$8,'My trades'!$E$2:$E$201,'Number of trades exchanged'!J2) -> 0 | ... L8: =COUNTIFS('My trades'!$C$2:$C$201,$B$8,'My trades'!$E$2:$E$201,'Number of trades exchanged'!L2) -> 1 | M8: =SUM(C8:L8) -> 8
B9: Canada | C9: =COUNTIFS('My trades'!$C$2:$C$201,$B$9,'My trades'!$E$2:$E$201,'Number of trades exchanged'!C2) -> 0 | D9: =COUNTIFS('My trades'!$C$2:$C$201,$B$9,'My trades'!$E$2:$E$201,'Number of trades exchanged'!D2) -> 2 | E9: =COUNTIFS('My trades'!$C$2:$C$201,$B$9,'My trades'!$E$2:$E$201,'Number of trades exchanged'!E2) -> 0 | F9: =COUNTIFS('My trades'!$C$2:$C$201,$B$9,'My trades'!$E$2:$E$201,'Number of trades exchanged'!F2) -> 0 | G9: =COUNTIFS('My trades'!$C$2:$C$201,$B$9,'My trades'!$E$2:$E$201,'Number of trades exchanged'!G2) -> 2 | H9: =COUNTIFS('My trades'!$C$2:$C$201,$B$9,'My trades'!$E$2:$E$201,'Number of trades exchanged'!H2) -> 2 | I9: =COUNTIFS('My trades'!$C$2:$C$201,$B$9,'My trades'!$E$2:$E$201,'Number of trades exchanged'!I2) -> 0 | J9: =COUNTIFS('My trades'!$C$2:$C$201,$B$9,'My trades'!$E$2:$E$201,'Number of trades exchanged'!J2) -> 0 | ... L9: =COUNTIFS('My trades'!$C$2:$C$201,$B$9,'My trades'!$E$2:$E$201,'Number of trades exchanged'!L2) -> 2 | M9: =SUM(C9:L9) -> 8
B10: Germany | C10: =COUNTIFS('My trades'!$C$2:$C$201,$B$10,'My trades'!$E$2:$E$201,'Number of trades exchanged'!C2) -> 1 | D10: =COUNTIFS('My trades'!$C$2:$C$201,$B$10,'My trades'!$E$2:$E$201,'Number of trades exchanged'!D2) -> 1 | E10: =COUNTIFS('My trades'!$C$2:$C$201,$B$10,'My trades'!$E$2:$E$201,'Number of trades exchanged'!E2) -> 3 | F10: =COUNTIFS('My trades'!$C$2:$C$201,$B$10,'My trades'!$E$2:$E$201,'Number of trades exchanged'!F2) -> 0 | G10: =COUNTIFS('My trades'!$C$2:$C$201,$B$10,'My trades'!$E$2:$E$201,'Number of trades exchanged'!G2) -> 4 | H10: =COUNTIFS('My trades'!$C$2:$C$201,$B$10,'My trades'!$E$2:$E$201,'Number of trades exchanged'!H2) -> 4 | I10: =COUNTIFS('My trades'!$C$2:$C$201,$B$10,'My trades'!$E$2:$E$201,'Number of trades exchanged'!I2) -> 1 | J10: =COUNTIFS('My trades'!$C$2:$C$201,$B$10,'My trades'!$E$2:$E$201,'Number of trades exchanged'!J2) -> 0 | ... L10: =COUNTIFS('My trades'!$C$2:$C$201,$B$10,'My trades'!$E$2:$E$201,'Number of trades exchanged'!L2) -> 0 | M10: =SUM(C10:L10) -> 16
B11: Saudi Arabia | C11: =COUNTIFS('My trades'!$C$2:$C$201,$B$11,'My trades'!$E$2:$E$201,'Number of trades exchanged'!C2) -> 1 | D11: =COUNTIFS('My trades'!$C$2:$C$201,$B$11,'My trades'!$E$2:$E$201,'Number of trades exchanged'!D2) -> 2 | E11: =COUNTIFS('My trades'!$C$2:$C$201,$B$11,'My trades'!$E$2:$E$201,'Number of trades exchanged'!E2) -> 0 | F11: =COUNTIFS('My trades'!$C$2:$C$201,$B$11,'My trades'!$E$2:$E$201,'Number of trades exchanged'!F2) -> 0 | G11: =COUNTIFS('My trades'!$C$2:$C$201,$B$11,'My trades'!$E$2:$E$201,'Number of trades exchanged'!G2) -> 2 | H11: =COUNTIFS('My trades'!$C$2:$C$201,$B$11,'My trades'!$E$2:$E$201,'Number of trades exchanged'!H2) -> 1 | I11: =COUNTIFS('My trades'!$C$2:$C$201,$B$11,'My trades'!$E$2:$E$201,'Number of trades exchanged'!I2) -> 2 | J11: =COUNTIFS('My trades'!$C$2:$C$201,$B$11,'My trades'!$E$2:$E$201,'Number of trades exchanged'!J2) -> 0 | ... L11: =COUNTIFS('My trades'!$C$2:$C$201,$B$11,'My trades'!$E$2:$E$201,'Number of trades exchanged'!L2) -> 0 | M11: =SUM(C11:L11) -> 8
B12: Japan | C12: =COUNTIFS('My trades'!$C$2:$C$201,$B$12,'My trades'!$E$2:$E$201,'Number of trades exchanged'!C2) -> 1 | D12: =COUNTIFS('My trades'!$C$2:$C$201,$B$12,'My trades'!$E$2:$E$201,'Number of trades exchanged'!D2) -> 1 | E12: =COUNTIFS('My trades'!$C$2:$C$201,$B$12,'My trades'!$E$2:$E$201,'Number of trades exchanged'!E2) -> 1 | F12: =COUNTIFS('My trades'!$C$2:$C$201,$B$12,'My trades'!$E$2:$E$201,'Number of trades exchanged'!F2) -> 0 | G12: =COUNTIFS('My trades'!$C$2:$C$201,$B$12,'My trades'!$E$2:$E$201,'Number of trades exchanged'!G2) -> 0 | H12: =COUNTIFS('My trades'!$C$2:$C$201,$B$12,'My trades'!$E$2:$E$201,'Number of trades exchanged'!H2) -> 2 | I12: =COUNTIFS('My trades'!$C$2:$C$201,$B$12,'My trades'!$E$2:$E$201,'Number of trades exchanged'!I2) -> 0 | J12: =COUNTIFS('My trades'!$C$2:$C$201,$B$12,'My trades'!$E$2:$E$201,'Number of trades exchanged'!J2) -> 2 | ... L12: =COUNTIFS('My trades'!$C$2:$C$201,$B$12,'My trades'!$E$2:$E$201,'Number of trades exchanged'!L2) -> 0 | M12: =SUM(C12:L12) -> 8
B13: Hong Kong | C13: =COUNTIFS('My trades'!$C$2:$C$201,$B$13,'My trades'!$E$2:$E$201,'Number of trades exchanged'!C2) -> 0 | D13: =COUNTIFS('My trades'!$C$2:$C$201,$B$13,'My trades'!$E$2:$E$201,'Number of trades exchanged'!D2) -> 0 | E13: =COUNTIFS('My trades'!$C$2:$C$201,$B$13,'My trades'!$E$2:$E$201,'Number of trades exchanged'!E2) -> 0 | F13: =COUNTIFS('My trades'!$C$2:$C$201,$B$13,'My trades'!$E$2:$E$201,'Number of trades exchanged'!F2) -> 0 | G13: =COUNTIFS('My trades'!$C$2:$C$201,$B$13,'My trades'!$E$2:$E$201,'Number of trades exchanged'!G2) -> 3 | H13: =COUNTIFS('My trades'!$C$2:$C$201,$B$13,'My trades'!$E$2:$E$201,'Number of trades exchanged'!H2) -> 1 | I13: =COUNTIFS('My trades'!$C$2:$C$201,$B$13,'My trades'!$E$2:$E$201,'Number of trades exchanged'!I2) -> 2 | J13: =COUNTIFS('My trades'!$C$2:$C$201,$B$13,'My trades'!$E$2:$E$201,'Number of trades exchanged'!J2) -> 0 | ... L13: =COUNTIFS('My trades'!$C$2:$C$201,$B$13,'My trades'!$E$2:$E$201,'Number of trades exchanged'!L2) -> 1 | M13: =SUM(C13:L13) -> 8
B14: China | C14: =COUNTIFS('My trades'!$C$2:$C$201,$B$14,'My trades'!$E$2:$E$201,'Number of trades exchanged'!C2) -> 2 | D14: =COUNTIFS('My trades'!$C$2:$C$201,$B$14,'My trades'!$E$2:$E$201,'Number of trades exchanged'!D2) -> 1 | E14: =COUNTIFS('My trades'!$C$2:$C$201,$B$14,'My trades'!$E$2:$E$201,'Number of trades exchanged'!E2) -> 1 | F14: =COUNTIFS('My trades'!$C$2:$C$201,$B$14,'My trades'!$E$2:$E$201,'Number of trades exchanged'!F2) -> 6 | G14: =COUNTIFS('My trades'!$C$2:$C$201,$B$14,'My trades'!$E$2:$E$201,'Number of trades exchanged'!G2) -> 1 | H14: =COUNTIFS('My trades'!$C$2:$C$201,$B$14,'My trades'!$E$2:$E$201,'Number of trades exchanged'!H2) -> 2 | I14: =COUNTIFS('My trades'!$C$2:$C$201,$B$14,'My trades'!$E$2:$E$201,'Number of trades exchanged'!I2) -> 0 | J14: =COUNTIFS('My trades'!$C$2:$C$201,$B$14,'My trades'!$E$2:$E$201,'Number of trades exchanged'!J2) -> 1 | ... L14: =COUNTIFS('My trades'!$C$2:$C$201,$B$14,'My trades'!$E$2:$E$201,'Number of trades exchanged'!L2) -> 0 | M14: =SUM(C14:L14) -> 16
B15: United Kingdom | C15: =COUNTIFS('My trades'!$C$2:$C$201,$B$15,'My trades'!$E$2:$E$201,'Number of trades exchanged'!C2) -> 1 | D15: =COUNTIFS('My trades'!$C$2:$C$201,$B$15,'My trades'!$E$2:$E$201,'Number of trades exchanged'!D2) -> 2 | E15: =COUNTIFS('My trades'!$C$2:$C$201,$B$15,'My trades'!$E$2:$E$201,'Number of trades exchanged'!E2) -> 0 | F15: =COUNTIFS('My trades'!$C$2:$C$201,$B$15,'My trades'!$E$2:$E$201,'Number of trades exchanged'!F2) -> 1 | G15: =COUNTIFS('My trades'!$C$2:$C$201,$B$15,'My trades'!$E$2:$E$201,'Number of trades exchanged'!G2) -> 0 | H15: =COUNTIFS('My trades'!$C$2:$C$201,$B$15,'My trades'!$E$2:$E$201,'Number of trades exchanged'!H2) -> 1 | I15: =COUNTIFS('My trades'!$C$2:$C$201,$B$15,'My trades'!$E$2:$E$201,'Number of trades exchanged'!I2) -> 2 | J15: =COUNTIFS('My trades'!$C$2:$C$201,$B$15,'My trades'!$E$2:$E$201,'Number of trades exchanged'!J2) -> 0 | ... L15: =COUNTIFS('My trades'!$C$2:$C$201,$B$15,'My trades'!$E$2:$E$201,'Number of trades exchanged'!L2) -> 0 | M15: =SUM(C15:L15) -> 8
B16: Brazil | C16: =COUNTIFS('My trades'!$C$2:$C$201,$B$16,'My trades'!$E$2:$E$201,'Number of trades exchanged'!C2) -> 2 | D16: =COUNTIFS('My trades'!$C$2:$C$201,$B$16,'My trades'!$E$2:$E$201,'Number of trades exchanged'!D2) -> 3 | E16: =COUNTIFS('My trades'!$C$2:$C$201,$B$16,'My trades'!$E$2:$E$201,'Number of trades exchanged'!E2) -> 1 | F16: =COUNTIFS('My trades'!$C$2:$C$201,$B$16,'My trades'!$E$2:$E$201,'Number of trades exchanged'!F2) -> 1 | G16: =COUNTIFS('My trades'!$C$2:$C$201,$B$16,'My trades'!$E$2:$E$201,'Number of trades exchanged'!G2) -> 0 | H16: =COUNTIFS('My trades'!$C$2:$C$201,$B$16,'My trades'!$E$2:$E$201,'Number of trades exchanged'!H2) -> 1 | I16: =COUNTIFS('My trades'!$C$2:$C$201,$B$16,'My trades'!$E$2:$E$201,'Number of trades exchanged'!I2) -> 4 | J16: =COUNTIFS('My trades'!$C$2:$C$201,$B$16,'My trades'!$E$2:$E$201,'Number of trades exchanged'!J2) -> 2 | ... L16: =COUNTIFS('My trades'!$C$2:$C$201,$B$16,'My trades'!$E$2:$E$201,'Number of trades exchanged'!L2) -> 0 | M16: =SUM(C16:L16) -> 16
B17: United States | C17: =COUNTIFS('My trades'!$C$2:$C$201,$B$17,'My trades'!$E$2:$E$201,'Number of trades exchanged'!C2) -> 2 | D17: =COUNTIFS('My trades'!$C$2:$C$201,$B$17,'My trades'!$E$2:$E$201,'Number of trades exchanged'!D2) -> 1 | E17: =COUNTIFS('My trades'!$C$2:$C$201,$B$17,'My trades'!$E$2:$E$201,'Number of trades exchanged'!E2) -> 3 | F17: =COUNTIFS('My trades'!$C$2:$C$201,$B$17,'My trades'!$E$2:$E$201,'Number of trades exchanged'!F2) -> 2 | G17: =COUNTIFS('My trades'!$C$2:$C$201,$B$17,'My trades'!$E$2:$E$201,'Number of trades exchanged'!G2) -> 0 | H17: =COUNTIFS('My trades'!$C$2:$C$201,$B$17,'My trades'!$E$2:$E$201,'Number of trades exchanged'!H2) -> 1 | I17: =COUNTIFS('My trades'!$C$2:$C$201,$B$17,'My trades'!$E$2:$E$201,'Number of trades exchanged'!I2) -> 1 | J17: =COUNTIFS('My trades'!$C$2:$C$201,$B$17,'My trades'!$E$2:$E$201,'Number of trades exchanged'!J2) -> 3 | ... L17: =COUNTIFS('My trades'!$C$2:$C$201,$B$17,'My trades'!$E$2:$E$201,'Number of trades exchanged'!L2) -> 3 | M17: =SUM(C17:L17) -> 16
B18: Taiwan | C18: =COUNTIFS('My trades'!$C$2:$C$201,$B$18,'My trades'!$E$2:$E$201,'Number of trades exchanged'!C2) -> 0 | D18: =COUNTIFS('My trades'!$C$2:$C$201,$B$18,'My trades'!$E$2:$E$201,'Number of trades exchanged'!D2) -> 0 | E18: =COUNTIFS('My trades'!$C$2:$C$201,$B$18,'My trades'!$E$2:$E$201,'Number of trades exchanged'!E2) -> 1 | F18: =COUNTIFS('My trades'!$C$2:$C$201,$B$18,'My trades'!$E$2:$E$201,'Number of trades exchanged'!F2) -> 1 | G18: =COUNTIFS('My trades'!$C$2:$C$201,$B$18,'My trades'!$E$2:$E$201,'Number of trades exchanged'!G2) -> 1 | H18: =COUNTIFS('My trades'!$C$2:$C$201,$B$18,'My trades'!$E$2:$E$201,'Number of trades exchanged'!H2) -> 0 | I18: =COUNTIFS('My trades'!$C$2:$C$201,$B$18,'My trades'!$E$2:$E$201,'Number of trades exchanged'!I2) -> 1 | J18: =COUNTIFS('My trades'!$C$2:$C$201,$B$18,'My trades'!$E$2:$E$201,'Number of trades exchanged'!J2) -> 0 | ... L18: =COUNTIFS('My trades'!$C$2:$C$201,$B$18,'My trades'!$E$2:$E$201,'Number of trades exchanged'!L2) -> 2 | M18: =SUM(C18:L18) -> 8
B19: Australia | C19: =COUNTIFS('My trades'!$C$2:$C$201,$B$19,'My trades'!$E$2:$E$201,'Number of trades exchanged'!C2) -> 3 | D19: =COUNTIFS('My trades'!$C$2:$C$201,$B$19,'My trades'!$E$2:$E$201,'Number of trades exchanged'!D2) -> 2 | E19: =COUNTIFS('My trades'!$C$2:$C$201,$B$19,'My trades'!$E$2:$E$201,'Number of trades exchanged'!E2) -> 1 | F19: =COUNTIFS('My trades'!$C$2:$C$201,$B$19,'My trades'!$E$2:$E$201,'Number of trades exchanged'!F2) -> 0 | G19: =COUNTIFS('My trades'!$C$2:$C$201,$B$19,'My trades'!$E$2:$E$201,'Number of trades exchanged'!G2) -> 3 | H19: =COUNTIFS('My trades'!$C$2:$C$201,$B$19,'My trades'!$E$2:$E$201,'Number of trades exchanged'!H2) -> 1 | I19: =COUNTIFS('My trades'!$C$2:$C$201,$B$19,'My trades'!$E$2:$E$201,'Number of trades exchanged'!I2) -> 3 | J19: =COUNTIFS('My trades'!$C$2:$C$201,$B$19,'My trades'!$E$2:$E$201,'Number of trades exchanged'!J2) -> 1 | ... L19: =COUNTIFS('My trades'!$C$2:$C$201,$B$19,'My trades'!$E$2:$E$201,'Number of trades exchanged'!L2) -> 2 | M19: =SUM(C19:L19) -> 16
B20: Distr. Marginale | C20: =SUM(C3:C19) -> 26 | D20: =SUM(D3:D19) -> 22 | E20: =SUM(E3:E19) -> 21 | F20: =SUM(F3:F19) -> 18 | G20: =SUM(G3:G19) -> 21 | H20: =SUM(H3:H19) -> 27 | I20: =SUM(I3:I19) -> 20 | J20: =SUM(J3:J19) -> 14 | ... L20: =SUM(L3:L19) -> 16 | M20: =SUM(C20:L20) -> 200 | N20: TOT
